{
 "cells": [
  {
   "cell_type": "code",
   "execution_count": 3,
   "id": "f9739b96-c7ca-40dd-8abc-f98f51171c95",
   "metadata": {},
   "outputs": [
    {
     "name": "stdout",
     "output_type": "stream",
     "text": [
      "Requirement already satisfied: folium in /opt/anaconda3/lib/python3.11/site-packages (0.16.0)\n",
      "Requirement already satisfied: branca>=0.6.0 in /opt/anaconda3/lib/python3.11/site-packages (from folium) (0.7.1)\n",
      "Requirement already satisfied: jinja2>=2.9 in /opt/anaconda3/lib/python3.11/site-packages (from folium) (3.1.3)\n",
      "Requirement already satisfied: numpy in /opt/anaconda3/lib/python3.11/site-packages (from folium) (1.26.4)\n",
      "Requirement already satisfied: requests in /opt/anaconda3/lib/python3.11/site-packages (from folium) (2.31.0)\n",
      "Requirement already satisfied: xyzservices in /opt/anaconda3/lib/python3.11/site-packages (from folium) (2022.9.0)\n",
      "Requirement already satisfied: MarkupSafe>=2.0 in /opt/anaconda3/lib/python3.11/site-packages (from jinja2>=2.9->folium) (2.1.3)\n",
      "Requirement already satisfied: charset-normalizer<4,>=2 in /opt/anaconda3/lib/python3.11/site-packages (from requests->folium) (2.0.4)\n",
      "Requirement already satisfied: idna<4,>=2.5 in /opt/anaconda3/lib/python3.11/site-packages (from requests->folium) (3.4)\n",
      "Requirement already satisfied: urllib3<3,>=1.21.1 in /opt/anaconda3/lib/python3.11/site-packages (from requests->folium) (2.0.7)\n",
      "Requirement already satisfied: certifi>=2017.4.17 in /opt/anaconda3/lib/python3.11/site-packages (from requests->folium) (2024.2.2)\n"
     ]
    }
   ],
   "source": [
    "!pip install  folium #"
   ]
  },
  {
   "cell_type": "code",
   "execution_count": 4,
   "id": "56a762c5-4c56-4187-b1b5-43df7b64e609",
   "metadata": {},
   "outputs": [
    {
     "ename": "FileNotFoundError",
     "evalue": "[Errno 2] No such file or directory: 'gps_track.txt'",
     "output_type": "error",
     "traceback": [
      "\u001b[0;31m---------------------------------------------------------------------------\u001b[0m",
      "\u001b[0;31mFileNotFoundError\u001b[0m                         Traceback (most recent call last)",
      "Cell \u001b[0;32mIn[4], line 3\u001b[0m\n\u001b[1;32m      1\u001b[0m \u001b[38;5;28;01mimport\u001b[39;00m \u001b[38;5;21;01mfolium\u001b[39;00m \n\u001b[1;32m      2\u001b[0m \u001b[38;5;28;01mimport\u001b[39;00m \u001b[38;5;21;01mcsv\u001b[39;00m \n\u001b[0;32m----> 3\u001b[0m gpsTrack \u001b[38;5;241m=\u001b[39m \u001b[38;5;28mopen\u001b[39m(\u001b[38;5;124m'\u001b[39m\u001b[38;5;124mgps_track.txt\u001b[39m\u001b[38;5;124m'\u001b[39m, \u001b[38;5;124m\"\u001b[39m\u001b[38;5;124mr\u001b[39m\u001b[38;5;124m\"\u001b[39m)\n\u001b[1;32m      5\u001b[0m csvReader \u001b[38;5;241m=\u001b[39m csv\u001b[38;5;241m.\u001b[39mreader(gpsTrack)\n\u001b[1;32m      6\u001b[0m header \u001b[38;5;241m=\u001b[39m csvReader\u001b[38;5;241m.\u001b[39m\u001b[38;5;21m__next__\u001b[39m()\n",
      "File \u001b[0;32m/opt/anaconda3/lib/python3.11/site-packages/IPython/core/interactiveshell.py:310\u001b[0m, in \u001b[0;36m_modified_open\u001b[0;34m(file, *args, **kwargs)\u001b[0m\n\u001b[1;32m    303\u001b[0m \u001b[38;5;28;01mif\u001b[39;00m file \u001b[38;5;129;01min\u001b[39;00m {\u001b[38;5;241m0\u001b[39m, \u001b[38;5;241m1\u001b[39m, \u001b[38;5;241m2\u001b[39m}:\n\u001b[1;32m    304\u001b[0m     \u001b[38;5;28;01mraise\u001b[39;00m \u001b[38;5;167;01mValueError\u001b[39;00m(\n\u001b[1;32m    305\u001b[0m         \u001b[38;5;124mf\u001b[39m\u001b[38;5;124m\"\u001b[39m\u001b[38;5;124mIPython won\u001b[39m\u001b[38;5;124m'\u001b[39m\u001b[38;5;124mt let you open fd=\u001b[39m\u001b[38;5;132;01m{\u001b[39;00mfile\u001b[38;5;132;01m}\u001b[39;00m\u001b[38;5;124m by default \u001b[39m\u001b[38;5;124m\"\u001b[39m\n\u001b[1;32m    306\u001b[0m         \u001b[38;5;124m\"\u001b[39m\u001b[38;5;124mas it is likely to crash IPython. If you know what you are doing, \u001b[39m\u001b[38;5;124m\"\u001b[39m\n\u001b[1;32m    307\u001b[0m         \u001b[38;5;124m\"\u001b[39m\u001b[38;5;124myou can use builtins\u001b[39m\u001b[38;5;124m'\u001b[39m\u001b[38;5;124m open.\u001b[39m\u001b[38;5;124m\"\u001b[39m\n\u001b[1;32m    308\u001b[0m     )\n\u001b[0;32m--> 310\u001b[0m \u001b[38;5;28;01mreturn\u001b[39;00m io_open(file, \u001b[38;5;241m*\u001b[39margs, \u001b[38;5;241m*\u001b[39m\u001b[38;5;241m*\u001b[39mkwargs)\n",
      "\u001b[0;31mFileNotFoundError\u001b[0m: [Errno 2] No such file or directory: 'gps_track.txt'"
     ]
    }
   ],
   "source": [
    "import folium \n",
    "import csv \n",
    "gpsTrack = open('gps_track.txt', \"r\")\n",
    "\n",
    "csvReader = csv.reader(gpsTrack)\n",
    "header = csvReader.__next__()\n",
    "latIndex = header.index(\"lat\")\n",
    "longIndex = header.index(\"long\")\n",
    "\n",
    "mapa = folium.Map(location=[40.78966141, -77.85948515], zoom_start = 12)\n",
    "for row in csvReader:\n",
    "    lat = row[latIndex]\n",
    "    lon = row[longIndex]\n",
    "    folium.Marker([lat,lon]).add_to(mapa)\n",
    "\n"
   ]
  },
  {
   "cell_type": "code",
   "execution_count": null,
   "id": "c48941da-2583-46ee-9e8e-6fdf0bce9b47",
   "metadata": {},
   "outputs": [],
   "source": []
  }
 ],
 "metadata": {
  "kernelspec": {
   "display_name": "Python 3 (ipykernel)",
   "language": "python",
   "name": "python3"
  },
  "language_info": {
   "codemirror_mode": {
    "name": "ipython",
    "version": 3
   },
   "file_extension": ".py",
   "mimetype": "text/x-python",
   "name": "python",
   "nbconvert_exporter": "python",
   "pygments_lexer": "ipython3",
   "version": "3.11.7"
  }
 },
 "nbformat": 4,
 "nbformat_minor": 5
}
